#VRML_SIM R2020b utf8
WorldInfo {
  title "Mihotel Patio"
  basicTimeStep 16
  defaultDamping Damping {
  }
  contactProperties [
    ContactProperties {
      softCFM 1e-05
    }
  ]
}
Viewpoint {
  orientation -0.8674450695716784 -0.46546787672442863 -0.17572338209082528 0.8590777148100441
  position -41.488287327849534 87.5233239258475 89.1591490131006
}
Background {
  backUrl [
    "textures/cubic/noon_sunny_empty_back.jpg"
  ]
  bottomUrl [
    "textures/cubic/noon_sunny_empty_bottom.jpg"
  ]
  frontUrl [
    "textures/cubic/noon_sunny_empty_front.jpg"
  ]
  leftUrl [
    "textures/cubic/noon_sunny_empty_left.jpg"
  ]
  rightUrl [
    "textures/cubic/noon_sunny_empty_right.jpg"
  ]
  topUrl [
    "textures/cubic/noon_sunny_empty_top.jpg"
  ]
  luminosity 2
}
TexturedBackgroundLight {
  texture "noon_sunny_empty"
  luminosity 3
}
DEF PLANE Solid {
  children [
    Shape {
      appearance PBRAppearance {
        baseColorMap ImageTexture {
          url [
            "textures/water.jpg"
          ]
        }
        transparency 0.2
        roughness 0.02
        IBLStrength 0.3
        emissiveColor 0 0.05 0.1
        textureTransform TextureTransform {
          scale 250 250
        }
      }
      geometry Plane {
        size 3000 3000
      }
    }
  ]
  name "solid(6)"
}
DEF ACKERMAN Robot {
  translation -48.6725 2.08 10.4967
  rotation 4.628502393797977e-05 0.9999999854879694 0.00016395657126976477 -3.1415
  children [
    DEF BODY_SHAPE Shape {
      appearance PBRAppearance {
        baseColorMap ImageTexture {
          url [
            "textures/webots_billboard.jpg"
          ]
        }
        roughness 1
        metalness 0.2
        textureTransform TextureTransform {
          rotation -1.5708
          scale 1 2
        }
      }
      geometry Box {
        size 0.4 0.1 0.2
      }
    }
    DEF REAR_RIGHT_WHEEL HingeJoint {
      jointParameters HingeJointParameters {
        position 5.248061821413556
        axis 0 0 1
        anchor 0.15 0 -0.13
      }
      device [
        RotationalMotor {
          name "rear_right_wheel"
        }
      ]
      endPoint Solid {
        translation 0.15 0 -0.13
        rotation 0 0 1 5.248061821413556
        children [
          DEF WHEEL_ROT Transform {
            rotation 1 0 0 1.5708
            children [
              Shape {
                appearance Rubber {
                }
                geometry DEF WHEEL_CYL Cylinder {
                  height 0.04
                  radius 0.08
                }
              }
            ]
          }
        ]
        name "rear right wheel"
        boundingObject DEF WHEEL_ROT_BOUND Transform {
          rotation 1 0 0 1.5708
          children [
            Shape {
              appearance PBRAppearance {
                baseColor 0.8 0.8 0.8
                roughness 1
                metalness 0
              }
              geometry DEF WHEEL_CYL Cylinder {
                height 0.04
                radius 0.08
              }
            }
          ]
        }
        physics Physics {
        }
      }
    }
    DEF REAR_LEFT_WHEEL HingeJoint {
      jointParameters HingeJointParameters {
        position 5.247951379215957
        axis 0 0 1
        anchor 0.15 0 0.13
      }
      device [
        RotationalMotor {
          name "rear_left_wheel"
        }
      ]
      endPoint Solid {
        translation 0.15 0 0.13
        rotation 0 0 0.9999999999999999 5.247951379215957
        children [
          USE WHEEL_ROT
        ]
        name "rear left wheel"
        boundingObject USE WHEEL_ROT_BOUND
        physics Physics {
        }
      }
    }
    DEF RIGHT_STEER HingeJoint {
      jointParameters HingeJointParameters {
        position 0.28822474130807213
        axis 0 1 0
        anchor -0.15 0 -0.13
      }
      device [
        RotationalMotor {
          name "right_steer"
          minPosition -0.7
          maxPosition 0.7
        }
      ]
      endPoint Solid {
        translation -0.15 0 -0.13
        rotation 0 1 0 0.2882247413080726
        children [
          DEF FRONT_RIGHT_WHEEL HingeJoint {
            jointParameters HingeJointParameters {
              position 5.248013620670332
              axis 0 0 1
            }
            device [
              RotationalMotor {
                name "front_right_wheel"
              }
            ]
            endPoint Solid {
              rotation 0 0 1 5.248013620670332
              children [
                USE WHEEL_ROT
              ]
              boundingObject USE WHEEL_ROT_BOUND
              physics Physics {
              }
            }
          }
        ]
        name "right steer"
        boundingObject DEF DUMMY Sphere {
          radius 0.01
        }
        physics Physics {
        }
      }
    }
    DEF LEFT_STEER HingeJoint {
      jointParameters HingeJointParameters {
        position 0.2882246699595801
        axis 0 1 0
        anchor -0.15 0 0.13
      }
      device [
        RotationalMotor {
          name "left_steer"
          minPosition -0.7
          maxPosition 0.7
        }
      ]
      endPoint Solid {
        translation -0.15 0 0.13
        rotation 0 1 0 0.2882246699595801
        children [
          DEF FRONT_LEFT_WHEEL HingeJoint {
            jointParameters HingeJointParameters {
              position 5.247929633286703
              axis 0 0 1
            }
            device [
              RotationalMotor {
                name "front_left_wheel"
              }
            ]
            endPoint Solid {
              rotation 0 0 1 5.247929633286703
              children [
                USE WHEEL_ROT
              ]
              boundingObject USE WHEEL_ROT_BOUND
              physics Physics {
              }
            }
          }
        ]
        name "left steer"
        boundingObject DEF DUMMY Sphere {
          radius 0.01
        }
        physics Physics {
        }
      }
    }
  ]
  name "ackerman"
  boundingObject DEF BODY_SHAPE Shape {
    appearance PBRAppearance {
      baseColor 0.8 0.8 0.8
      roughness 1
      metalness 0
    }
    geometry Box {
      size 0.4 0.1 0.2
    }
  }
  physics Physics {
  }
  controller "mihotel_rover"
}
DEF TREES Group {
  children [
    PalmTree {
      translation 35.7794 1.98658 -7.25645
      rotation -0.21949292850183635 0.8191597331649041 0.5299058273871791 -0.9363253071795858
      name "palm tree(10)"
    }
    PalmTree {
      translation 31.4516 1.93 -6.92183
      rotation 0 1 0 0.523598
      name "palm tree(9)"
    }
    PalmTree {
      translation 23.4829 1.55107 -9.64
      rotation 0 0 1 -0.261795307179586
      name "palm tree(8)"
    }
    PalmTree {
      translation 30.501 1.83363 -8.94174
      rotation 0.3134610420923352 -0.5736250770278146 0.7567671016205851 -0.24932530717958645
      name "palm tree(7)"
    }
    PalmTree {
      translation 28.7056 1.71 -6.155
      rotation 0 1 0 0.785398
      name "palm tree(6)"
    }
    PalmTree {
      translation 26.1 1.52 -7.26
      name "palm tree(5)"
    }
    PalmTree {
      translation 16.16 2 -8.79
      name "palm tree(4)"
    }
    PalmTree {
      translation 24.2875 1.08 -4.82082
      rotation 0 1 0 0.261799
      name "palm tree(3)"
    }
    PalmTree {
      translation 22.44 2 -6.26
      name "palm tree(2)"
    }
    PalmTree {
      translation 17.0067 1.73937 -7.36003
      rotation 0.6215188306653532 0.4769078700650378 0.6215088306680776 -0.4715753071795863
      name "palm tree(1)"
    }
    PalmTree {
      translation 19.61 2 -4.65
      rotation -0.09269054311745581 0.7040524530580069 -0.7040728702056303 0.238811
    }
  ]
}
DEF SAND_GROUND Group {
  children [
    Solid {
      translation 0 1 -8
      children [
        Shape {
          appearance SandyGround {
            textureTransform TextureTransform {
              scale 100 14
            }
          }
          geometry DEF sandground Box {
            size 100 2 14
          }
        }
      ]
      name "solid(1)"
      boundingObject USE sandground
      locked TRUE
    }
    Solid {
      translation 35 1 10.5
      children [
        Shape {
          appearance SandyGround {
            textureTransform TextureTransform {
              scale 30 9
            }
          }
          geometry DEF sandground Box {
            size 30 2 9
          }
        }
      ]
      name "solid(3)"
      boundingObject USE sandground
      locked TRUE
    }
    Solid {
      translation 0 1 3.5
      children [
        Shape {
          appearance SandyGround {
            textureTransform TextureTransform {
              scale 100 5
            }
          }
          geometry DEF sandground Box {
            size 100 2 5
          }
        }
      ]
      name "solid(2)"
      boundingObject USE sandground
      locked TRUE
    }
    Solid {
      translation -30 1 7
      children [
        Shape {
          appearance SandyGround {
            textureTransform TextureTransform {
              scale 40 2
              translation 0 -1
            }
          }
          geometry DEF sandground Box {
            size 40 2 2
          }
        }
      ]
      name "solid(5)"
      boundingObject USE sandground
      locked TRUE
    }
    Solid {
      translation -36.25 1 9.5
      children [
        Shape {
          appearance SandyGround {
            textureTransform TextureTransform {
              scale 27.5 3
              translation 0 -1.65
            }
          }
          geometry DEF sandground Box {
            size 27.5 2 3
          }
        }
      ]
      name "solid(4)"
      boundingObject USE sandground
      locked TRUE
    }
    Solid {
      translation -42.5 1 13
      children [
        Shape {
          appearance SandyGround {
            textureTransform TextureTransform {
              scale 15 4
              translation 0 -2.237
            }
          }
          geometry DEF sandground Box {
            size 15 2 4
          }
        }
      ]
      boundingObject USE sandground
      locked TRUE
    }
  ]
}
RubberDuck {
  translation -3.56331e-16 2.27044 7.02193e-07
  rotation 0.9999999999999998 2.6916945000513237e-08 1.0915634054343394e-09 1.6871810473485198e-07
  scale 12
  immersionProperties [
    ImmersionProperties {
      fluidName "fluid"
      dragForceCoefficients 0.1 0 0
      dragTorqueCoefficients 0.05 0 0
      viscousResistanceForceCoefficient 400
      viscousResistanceTorqueCoefficient 0.5
    }
  ]
}
DEF RIVER Fluid {
  translation 0 1 0
  children [
    Shape {
      appearance PBRAppearance {
        baseColor 0.0627 0.552 0.8
        baseColorMap ImageTexture {
          url [
            "textures/water.jpg"
          ]
        }
        transparency 0.5
        roughness 0.001
        metalness 0
        textureTransform TextureTransform {
          scale 20 0.4
        }
      }
      geometry DEF water_box Box {
        size 100 2 2
      }
    }
  ]
  boundingObject USE water_box
  locked TRUE
}
DEF POND Fluid {
  translation -7.5 0.95 10.5
  children [
    Shape {
      appearance PBRAppearance {
        baseColor 0.0627 0.552 0.8
        baseColorMap ImageTexture {
          url [
            "textures/water.jpg"
          ]
        }
        transparency 0.5
        roughness 0.001
        metalness 0
        textureTransform TextureTransform {
          scale 11 1.8
        }
      }
      geometry DEF water_box Box {
        size 55 1.9 9
      }
    }
  ]
  boundingObject USE water_box
  locked TRUE
}
RectangleArena {
  floorSize 100 30
  floorTileSize 100 30
  floorAppearance Soil {
    textureTransform TextureTransform {
      scale 20 6
    }
  }
  wallThickness 0.5
  wallHeight 2
  wallAppearance FormedConcrete {
    textureTransform TextureTransform {
      scale 3 3
    }
  }
}
DEF path1 Group {
  children [
    StraightRoadSegment {
      translation -48 2.01 4.1
      rotation 0 1 0 1.5708
      name "road(8)"
      width 0.2
      numberOfLanes 1
      rightBorder FALSE
      leftBorder FALSE
      length 68
      appearance Asphalt {
        textureTransform TextureTransform {
          scale 8 8
        }
      }
    }
    CurvedRoadSegment {
      translation -48 2.01 4.9
      rotation 0 1 0 -1.5708
      name "road(7)"
      width 0.2
      numberOfLanes 1
      rightBorder FALSE
      leftBorder FALSE
      curvatureRadius 0.8
      totalAngle 3.1415
      appearance Asphalt {
        textureTransform TextureTransform {
          scale 8 8
        }
      }
    }
    StraightRoadSegment {
      translation -48 2.01 5.7
      rotation 0 1 0 1.5708
      name "road(6)"
      width 0.2
      numberOfLanes 1
      rightBorder FALSE
      leftBorder FALSE
      length 35
      appearance Asphalt {
        textureTransform TextureTransform {
          scale 8 8
        }
      }
    }
    CurvedRoadSegment {
      translation -13 2.01 6.5
      rotation 0 1 0 1.5708
      name "road(5)"
      width 0.2
      numberOfLanes 1
      rightBorder FALSE
      leftBorder FALSE
      curvatureRadius 0.8
      totalAngle 3.1415
      appearance Asphalt {
        textureTransform TextureTransform {
          scale 8 8
        }
      }
    }
    StraightRoadSegment {
      translation -48 2.01 7.3
      rotation 0 1 0 1.5708
      name "road(4)"
      width 0.2
      numberOfLanes 1
      rightBorder FALSE
      leftBorder FALSE
      length 35
      appearance Asphalt {
        textureTransform TextureTransform {
          scale 8 8
        }
      }
    }
    CurvedRoadSegment {
      translation -48 2.01 8.1
      rotation 0 1 0 -1.5708
      name "road(3)"
      width 0.2
      numberOfLanes 1
      rightBorder FALSE
      leftBorder FALSE
      curvatureRadius 0.8
      totalAngle 3.1415
      appearance Asphalt {
        textureTransform TextureTransform {
          scale 8 8
        }
      }
    }
    StraightRoadSegment {
      translation -48 2.01 8.9
      rotation 0 1 0 1.5708
      name "road(2)"
      width 0.2
      numberOfLanes 1
      rightBorder FALSE
      leftBorder FALSE
      length 23
      appearance Asphalt {
        textureTransform TextureTransform {
          scale 8 8
        }
      }
    }
    CurvedRoadSegment {
      translation -25 2.01 9.7
      rotation 0 1 0 1.5708
      name "road(1)"
      width 0.2
      numberOfLanes 1
      rightBorder FALSE
      leftBorder FALSE
      curvatureRadius 0.8
      totalAngle 3.1415
      appearance Asphalt {
        textureTransform TextureTransform {
          scale 8 8
        }
      }
    }
    StraightRoadSegment {
      translation -50 2.01 10.5
      rotation 0 1 0 1.5708
      width 0.2
      numberOfLanes 1
      rightBorder FALSE
      leftBorder FALSE
      length 25
      appearance Asphalt {
        textureTransform TextureTransform {
          scale 8 8
        }
      }
    }
  ]
}
Bridge {
  translation 20 2 0
  rotation 0 1 0 1.5708
  name "ramp 20 degrees"
}
